Workbook

Sheet NOTES
A1: Sources (as of Feb-2019)
A3: 1 | B3: NFIB | C3: http://www.nfib-sbet.org/indicators/
C4: Historical data available in Excel format BUT it is sometimes delayed.
A5: 2 | B5: Investing.com | C5: https://www.investing.com/economic-calendar/nfib-small-business-optimism-537
C6: Another way to view the entire historical dataset, and up to date. However the only way to get all of this data from the website is manually. The easiest way to do that is to copy and paste the data. Note this only provides data for the headline index.
A11: Updating (Monthly)
A13: 1 | B13: NFIB SBO Core Index
C14: Copy down (autofill) cells in columns A-D down to a new row to input new data. Replace the data in column B for the new month.
C15: Double check the historical data in the report for any backwards revisions and edit data as necessary.
A16: 2 | B16: SBO_vs_GDP
C17: Not required - more a proof of concept. But if you do update it then:
C18: Copy down (autofill) cells in columns A-F down to a new row. Backfill GDP data in column E observed from FRED calculate the GDP YoY percentage change in column F. Note GDP data is quarterly and so one data point is required for every 3 months.
C19: Columns A to D will auto update based on data in "NFIB SBO Core Index" sheet
A20: 3 | B20: SBO_vs_SP500
C21: Not required - more a proof of concept. But if you do update it then:
C22: Copy down (autofill) cells in columns A-F down to a new row. Backfill S&P500 data in column E observed from Yahoo Finance (or other source) and calculate the S&P500 YoY percentage change in column F.
C23: Columns A to D will auto update based on data in "NFIB SBO Core Index" sheet
A24: 4 | B24: SBO_Leading_vs_GDP
C25: Not required - more a proof of concept. But if you do update it then:
C26: Copy down (autofill) cells in columns A-F down to a new row. Backfill GDP data in column E observed from FRED calculate the GDP YoY percentage change in column F. Note GDP data is quarterly and so one data point is required for every 3 months.
C27: Columns A to D will auto update based on data in core index and leading indices sheets
A28: 5 | B28: SBO_Leading_vs_SP500
C29: Not required - more a proof of concept. But if you do update it then:
C30: Copy down (autofill) cells in columns A-F down to a new row. Backfill S&P500 data in column E observed from Yahoo Finance (or other source) and calculate the S&P500 YoY percentage change in column F.
C31: Columns A to D will auto update based on data in core index and leading indices sheets
A32: 6 | B32: Sub-Indices
C33: Go to | D33: http://www.nfib-sbet.org/indicators/
C34: With the indicator set to Small Business Optimism, select the sub-index you wish to update from the indicator selector drop-down menu.
C35: Click "Show Results" (it can take a while to load)
C36: Observe lastest result and update the sub-index accordingly, or download the entire dataset and update.
D37: Note, if you download the historical dataset in Excel form you will need to transform the values from Text to Number format
A40: Index Explanation
B41: Small Business Optimism | C41: The Index of Small Business Optimism consists of 10 equally weighted and seasonally adjusted variables. The monthly change of each variable contributes proportionally to the overall monthly change in the Index.
B42: Plans to Increase Employment | C42: The percent of respondents who plan to "increase" their number of employees minus those who plan to "decrease" their number of employees in the next three months.
B43: Plans to Make Capital Outlays | C43: The percent of respondents planning a capital expenditure during the next three to six months.
B44: Plans to Increase Inventories | C44: The percent of respondents who plan to "increase" inventories minus those who plan to "decrease" inventories in the next three to six months.
B45: Expect Economy to Improve | C45: The percent of respondents who think general business condition will be "better" minus those who think it will be "worse" six months from now. Example: A net, negative 28 percent means 28 percent more small business owners think that general business conditions will be worse than those who think it will be better six months from now.
B46: Expect Retail Sales Higher | C46: The percent of respondents who think sales will be "higher" minus those who think sales will be "lower" during the next three months.
B47: Current Inventory | C47: The percent of respondents who report that their inventories are currently "too low" minus those who report their inventories are currently "too large".
B48: Current Job Openings | C48: The percent of respondents with a position they are currently not able to fill.
...

Sheet NFIB SBO Core Index
A1: Date | B1: Small Business Optimism Index | C1: Small Business Optimism Index MoM | D1: Small Business Optimism Index YoY
A2: 31443 | B2: 100.285
A3: 31471 | B3: 99.7915 | C3: =B3-B2 -> -0.4935
A4: 31502 | B4: 101.463 | C4: =B4-B3 -> 1.6715
A5: 31532 | B5: 101.015 | C5: =B5-B4 -> -0.448
A6: 31563 | B6: 101.956 | C6: =B6-B5 -> 0.941
A7: 31593 | B7: 101.289 | C7: =B7-B6 -> -0.667
A8: 31624 | B8: 99.8372 | C8: =B8-B7 -> -1.4518
A9: 31655 | B9: 98.8144 | C9: =B9-B8 -> -1.0228
A10: 31685 | B10: 98.5861 | C10: =B10-B9 -> -0.2283
A11: 31716 | B11: 98.7596 | C11: =B11-B10 -> 0.1735
A12: 31746 | B12: 97.536 | C12: =B12-B11 -> -1.2236
A13: 31777 | B13: 100.668 | C13: =B13-B12 -> 3.132
A14: 31808 | B14: 100.102 | C14: =B14-B13 -> -0.566 | D14: =B14-B2 -> -0.183
A15: 31836 | B15: 100.613 | C15: =B15-B14 -> 0.511 | D15: =B15-B3 -> 0.8215
A16: 31867 | B16: 101.189 | C16: =B16-B15 -> 0.576 | D16: =B16-B4 -> -0.274
A17: 31897 | B17: 100.102 | C17: =B17-B16 -> -1.087 | D17: =B17-B5 -> -0.913
A18: 31928 | B18: 99.8554 | C18: =B18-B17 -> -0.2466 | D18: =B18-B6 -> -2.1006
A19: 31958 | B19: 101.746 | C19: =B19-B18 -> 1.8906 | D19: =B19-B7 -> 0.457
A20: 31989 | B20: 102.485 | C20: =B20-B19 -> 0.739 | D20: =B20-B8 -> 2.6478
A21: 32020 | B21: 103.745 | C21: =B21-B20 -> 1.26 | D21: =B21-B9 -> 4.9306
A22: 32050 | B22: 102.421 | C22: =B22-B21 -> -1.324 | D22: =B22-B10 -> 3.8349
A23: 32081 | B23: 101.59 | C23: =B23-B22 -> -0.831 | D23: =B23-B11 -> 2.8304
A24: 32111 | B24: 98.6318 | C24: =B24-B23 -> -2.9582 | D24: =B24-B12 -> 1.0958
A25: 32142 | B25: 100.029 | C25: =B25-B24 -> 1.3972 | D25: =B25-B13 -> -0.639
... A421: 44196 | B421: 95.708 | C421: =B421-B420 -> -5.479 | D421: =B421-B409 -> -6.575

Sheet SBO_vs_GDP
A1: Date | B1: Small Business Optimism Index | C1: Small Business Optimism Index MoM | D1: Small Business Optimism Index YoY | E1: US Real GDP, Billions 2012 USD, Seasonally Adjusted | F1: GDP YoY %
A2: ='NFIB SBO Core Index'!A2 -> 31443 | B2: =VLOOKUP(A2,'NFIB SBO Core Index'!A:B,2,FALSE) -> 100.285
A3: ='NFIB SBO Core Index'!A3 -> 31471 | B3: =VLOOKUP(A3,'NFIB SBO Core Index'!A:B,2,FALSE) -> 99.7915 | C3: =B3-B2 -> -0.4935
A4: ='NFIB SBO Core Index'!A4 -> 31502 | B4: =VLOOKUP(A4,'NFIB SBO Core Index'!A:B,2,FALSE) -> 101.463 | C4: =B4-B3 -> 1.6715 | E4: 8148.603
A5: ='NFIB SBO Core Index'!A5 -> 31532 | B5: =VLOOKUP(A5,'NFIB SBO Core Index'!A:B,2,FALSE) -> 101.015 | C5: =B5-B4 -> -0.448
A6: ='NFIB SBO Core Index'!A6 -> 31563 | B6: =VLOOKUP(A6,'NFIB SBO Core Index'!A:B,2,FALSE) -> 101.956 | C6: =B6-B5 -> 0.941
A7: ='NFIB SBO Core Index'!A7 -> 31593 | B7: =VLOOKUP(A7,'NFIB SBO Core Index'!A:B,2,FALSE) -> 101.289 | C7: =B7-B6 -> -0.667 | E7: 8185.303
A8: ='NFIB SBO Core Index'!A8 -> 31624 | B8: =VLOOKUP(A8,'NFIB SBO Core Index'!A:B,2,FALSE) -> 99.8372 | C8: =B8-B7 -> -1.4518
A9: ='NFIB SBO Core Index'!A9 -> 31655 | B9: =VLOOKUP(A9,'NFIB SBO Core Index'!A:B,2,FALSE) -> 98.8144 | C9: =B9-B8 -> -1.0228
A10: ='NFIB SBO Core Index'!A10 -> 31685 | B10: =VLOOKUP(A10,'NFIB SBO Core Index'!A:B,2,FALSE) -> 98.5861 | C10: =B10-B9 -> -0.2283 | E10: 8263.639
A11: ='NFIB SBO Core Index'!A11 -> 31716 | B11: =VLOOKUP(A11,'NFIB SBO Core Index'!A:B,2,FALSE) -> 98.7596 | C11: =B11-B10 -> 0.1735
A12: ='NFIB SBO Core Index'!A12 -> 31746 | B12: =VLOOKUP(A12,'NFIB SBO Core Index'!A:B,2,FALSE) -> 97.536 | C12: =B12-B11 -> -1.2236
A13: ='NFIB SBO Core Index'!A13 -> 31777 | B13: =VLOOKUP(A13,'NFIB SBO Core Index'!A:B,2,FALSE) -> 100.668 | C13: =B13-B12 -> 3.132 | E13: 8308.021
A14: ='NFIB SBO Core Index'!A14 -> 31808 | B14: =VLOOKUP(A14,'NFIB SBO Core Index'!A:B,2,FALSE) -> 100.102 | C14: =B14-B13 -> -0.566 | D14: =B14-B2 -> -0.183
A15: ='NFIB SBO Core Index'!A15 -> 31836 | B15: =VLOOKUP(A15,'NFIB SBO Core Index'!A:B,2,FALSE) -> 100.613 | C15: =B15-B14 -> 0.511 | D15: =B15-B3 -> 0.8215
A16: ='NFIB SBO Core Index'!A16 -> 31867 | B16: =VLOOKUP(A16,'NFIB SBO Core Index'!A:B,2,FALSE) -> 101.189 | C16: =B16-B15 -> 0.576 | D16: =B16-B4 -> -0.274 | E16: 8369.93 | F16: =(E16-E4)/E4 -> 0.027161343
A17: ='NFIB SBO Core Index'!A17 -> 31897 | B17: =VLOOKUP(A17,'NFIB SBO Core Index'!A:B,2,FALSE) -> 100.102 | C17: =B17-B16 -> -1.087 | D17: =B17-B5 -> -0.913
A18: ='NFIB SBO Core Index'!A18 -> 31928 | B18: =VLOOKUP(A18,'NFIB SBO Core Index'!A:B,2,FALSE) -> 99.8554 | C18: =B18-B17 -> -0.2466 | D18: =B18-B6 -> -2.1006
A19: ='NFIB SBO Core Index'!A19 -> 31958 | B19: =VLOOKUP(A19,'NFIB SBO Core Index'!A:B,2,FALSE) -> 101.746 | C19: =B19-B18 -> 1.8906 | D19: =B19-B7 -> 0.457 | E19: 8460.233 | F19: =(E19-E7)/E7 -> 0.03358825
A20: ='NFIB SBO Core Index'!A20 -> 31989 | B20: =VLOOKUP(A20,'NFIB SBO Core Index'!A:B,2,FALSE) -> 102.485 | C20: =B20-B19 -> 0.739 | D20: =B20-B8 -> 2.6478
A21: ='NFIB SBO Core Index'!A21 -> 32020 | B21: =VLOOKUP(A21,'NFIB SBO Core Index'!A:B,2,FALSE) -> 103.745 | C21: =B21-B20 -> 1.26 | D21: =B21-B9 -> 4.9306
A22: ='NFIB SBO Core Index'!A22 -> 32050 | B22: =VLOOKUP(A22,'NFIB SBO Core Index'!A:B,2,FALSE) -> 102.421 | C22: =B22-B21 -> -1.324 | D22: =B22-B10 -> 3.8349 | E22: 8533.635 | F22: =(E22-E10)/E10 -> 0.032672773
A23: ='NFIB SBO Core Index'!A23 -> 32081 | B23: =VLOOKUP(A23,'NFIB SBO Core Index'!A:B,2,FALSE) -> 101.59 | C23: =B23-B22 -> -0.831 | D23: =B23-B11 -> 2.8304
A24: ='NFIB SBO Core Index'!A24 -> 32111 | B24: =VLOOKUP(A24,'NFIB SBO Core Index'!A:B,2,FALSE) -> 98.6318 | C24: =B24-B23 -> -2.9582 | D24: =B24-B12 -> 1.0958
A25: ='NFIB SBO Core Index'!A25 -> 32142 | B25: =VLOOKUP(A25,'NFIB SBO Core Index'!A:B,2,FALSE) -> 100.029 | C25: =B25-B24 -> 1.3972 | D25: =B25-B13 -> -0.639 | E25: 8680.162 | F25: =(E25-E13)/E13 -> 0.044792978
A26: ='NFIB SBO Core Index'!A26 -> 32173 | B26: =VLOOKUP(A26,'NFIB SBO Core Index'!A:B,2,FALSE) -> 100.376 | C26: =B26-B25 -> 0.347 | D26: =B26-B14 -> 0.274
A27: ='NFIB SBO Core Index'!A27 -> 32202 | B27: =VLOOKUP(A27,'NFIB SBO Core Index'!A:B,2,FALSE) -> 99.061 | C27: =B27-B26 -> -1.315 | D27: =B27-B15 -> -1.552
A28: ='NFIB SBO Core Index'!A28 -> 32233 | B28: =VLOOKUP(A28,'NFIB SBO Core Index'!A:B,2,FALSE) -> 101.554 | C28: =B28-B27 -> 2.493 | D28: =B28-B16 -> 0.365 | E28: 8725.006 | F28: =(E28-E16)/E16 -> 0.042422816
A29: ='NFIB SBO Core Index'!A29 -> 32263 | B29: =VLOOKUP(A29,'NFIB SBO Core Index'!A:B,2,FALSE) -> 100.65 | C29: =B29-B28 -> -0.904 | D29: =B29-B17 -> 0.548
A30: ='NFIB SBO Core Index'!A30 -> 32294 | B30: =VLOOKUP(A30,'NFIB SBO Core Index'!A:B,2,FALSE) -> 100.951 | C30: =B30-B29 -> 0.301 | D30: =B30-B18 -> 1.0956
A31: ='NFIB SBO Core Index'!A31 -> 32324 | B31: =VLOOKUP(A31,'NFIB SBO Core Index'!A:B,2,FALSE) -> 101.654 | C31: =B31-B30 -> 0.703 | D31: =B31-B19 -> -0.092 | E31: 8839.641 | F31: =(E31-E19)/E19 -> 0.044846046
A32: ='NFIB SBO Core Index'!A32 -> 32355 | B32: =VLOOKUP(A32,'NFIB SBO Core Index'!A:B,2,FALSE) -> 100.111 | C32: =B32-B31 -> -1.543 | D32: =B32-B20 -> -2.374
A33: ='NFIB SBO Core Index'!A33 -> 32386 | B33: =VLOOKUP(A33,'NFIB SBO Core Index'!A:B,2,FALSE) -> 101.645 | C33: =B33-B32 -> 1.534 | D33: =B33-B21 -> -2.1
A34: ='NFIB SBO Core Index'!A34 -> 32416 | B34: =VLOOKUP(A34,'NFIB SBO Core Index'!A:B,2,FALSE) -> 100.778 | C34: =B34-B33 -> -0.867 | D34: =B34-B22 -> -1.643 | E34: 8891.435 | F34: =(E34-E22)/E22 -> 0.041928205
A35: ='NFIB SBO Core Index'!A35 -> 32447 | B35: =VLOOKUP(A35,'NFIB SBO Core Index'!A:B,2,FALSE) -> 102.138 | C35: =B35-B34 -> 1.36 | D35: =B35-B23 -> 0.548
A36: ='NFIB SBO Core Index'!A36 -> 32477 | B36: =VLOOKUP(A36,'NFIB SBO Core Index'!A:B,2,FALSE) -> 101.828 | C36: =B36-B35 -> -0.31 | D36: =B36-B24 -> 3.1962
A37: ='NFIB SBO Core Index'!A37 -> 32508 | B37: =VLOOKUP(A37,'NFIB SBO Core Index'!A:B,2,FALSE) -> 100.485 | C37: =B37-B36 -> -1.343 | D37: =B37-B25 -> 0.456 | E37: 9009.913 | F37: =(E37-E25)/E25 -> 0.037989038
A38: ='NFIB SBO Core Index'!A38 -> 32539 | B38: =VLOOKUP(A38,'NFIB SBO Core Index'!A:B,2,FALSE) -> 101.289 | C38: =B38-B37 -> 0.804 | D38: =B38-B26 -> 0.913
A39: ='NFIB SBO Core Index'!A39 -> 32567 | B39: =VLOOKUP(A39,'NFIB SBO Core Index'!A:B,2,FALSE) -> 101.892 | C39: =B39-B38 -> 0.603 | D39: =B39-B27 -> 2.831
A40: ='NFIB SBO Core Index'!A40 -> 32598 | B40: =VLOOKUP(A40,'NFIB SBO Core Index'!A:B,2,FALSE) -> 101.371 | C40: =B40-B39 -> -0.521 | D40: =B40-B28 -> -0.183 | E40: 9101.508 | F40: =(E40-E28)/E28 -> 0.043152062
...

Sheet SBO_vs_SP500
A1: Date | B1: Small Business Optimism Index | C1: Small Business Optimism Index MoM | D1: Small Business Optimism Index YoY | E1: S&P 500 Index | F1: S&P 500 Index YoY %
A2: 31443 | B2: =VLOOKUP(A2,'NFIB SBO Core Index'!A:B,2,FALSE) -> 100.285 | E2: 211.78
A3: 31471 | B3: =VLOOKUP(A3,'NFIB SBO Core Index'!A:B,2,FALSE) -> 99.7915 | C3: =B3-B2 -> -0.4935 | E3: 226.92
A4: 31502 | B4: =VLOOKUP(A4,'NFIB SBO Core Index'!A:B,2,FALSE) -> 101.463 | C4: =B4-B3 -> 1.6715 | E4: 238.89999
A5: 31532 | B5: =VLOOKUP(A5,'NFIB SBO Core Index'!A:B,2,FALSE) -> 101.015 | C5: =B5-B4 -> -0.448 | E5: 235.52
A6: 31563 | B6: =VLOOKUP(A6,'NFIB SBO Core Index'!A:B,2,FALSE) -> 101.956 | C6: =B6-B5 -> 0.941 | E6: 247.35001
A7: 31593 | B7: =VLOOKUP(A7,'NFIB SBO Core Index'!A:B,2,FALSE) -> 101.289 | C7: =B7-B6 -> -0.667 | E7: 250.84
A8: 31624 | B8: =VLOOKUP(A8,'NFIB SBO Core Index'!A:B,2,FALSE) -> 99.8372 | C8: =B8-B7 -> -1.4518 | E8: 236.11999
A9: 31655 | B9: =VLOOKUP(A9,'NFIB SBO Core Index'!A:B,2,FALSE) -> 98.8144 | C9: =B9-B8 -> -1.0228 | E9: 252.92999
A10: 31685 | B10: =VLOOKUP(A10,'NFIB SBO Core Index'!A:B,2,FALSE) -> 98.5861 | C10: =B10-B9 -> -0.2283 | E10: 231.32001
A11: 31716 | B11: =VLOOKUP(A11,'NFIB SBO Core Index'!A:B,2,FALSE) -> 98.7596 | C11: =B11-B10 -> 0.1735 | E11: 243.98
A12: 31746 | B12: =VLOOKUP(A12,'NFIB SBO Core Index'!A:B,2,FALSE) -> 97.536 | C12: =B12-B11 -> -1.2236 | E12: 249.22
A13: 31777 | B13: =VLOOKUP(A13,'NFIB SBO Core Index'!A:B,2,FALSE) -> 100.668 | C13: =B13-B12 -> 3.132 | E13: 242.17
A14: 31808 | B14: =VLOOKUP(A14,'NFIB SBO Core Index'!A:B,2,FALSE) -> 100.102 | C14: =B14-B13 -> -0.566 | D14: =B14-B2 -> -0.183 | E14: 274.07999 | F14: =(E14-E2)/E2 -> 0.29417314
A15: 31836 | B15: =VLOOKUP(A15,'NFIB SBO Core Index'!A:B,2,FALSE) -> 100.613 | C15: =B15-B14 -> 0.511 | D15: =B15-B3 -> 0.8215 | E15: 284.20001 | F15: =(E15-E3)/E3 -> 0.25242383
A16: 31867 | B16: =VLOOKUP(A16,'NFIB SBO Core Index'!A:B,2,FALSE) -> 101.189 | C16: =B16-B15 -> 0.576 | D16: =B16-B4 -> -0.274 | E16: 291.70001 | F16: =(E16-E4)/E4 -> 0.22101306
A17: 31897 | B17: =VLOOKUP(A17,'NFIB SBO Core Index'!A:B,2,FALSE) -> 100.102 | C17: =B17-B16 -> -1.087 | D17: =B17-B5 -> -0.913 | E17: 288.35998 | F17: =(E17-E5)/E5 -> 0.22435454
A18: 31928 | B18: =VLOOKUP(A18,'NFIB SBO Core Index'!A:B,2,FALSE) -> 99.8554 | C18: =B18-B17 -> -0.2466 | D18: =B18-B6 -> -2.1006 | E18: 290.10001 | F18: =(E18-E6)/E6 -> 0.17283202
A19: 31958 | B19: =VLOOKUP(A19,'NFIB SBO Core Index'!A:B,2,FALSE) -> 101.746 | C19: =B19-B18 -> 1.8906 | D19: =B19-B7 -> 0.457 | E19: 304 | F19: =(E19-E7)/E7 -> 0.21192794
A20: 31989 | B20: =VLOOKUP(A20,'NFIB SBO Core Index'!A:B,2,FALSE) -> 102.485 | C20: =B20-B19 -> 0.739 | D20: =B20-B8 -> 2.6478 | E20: 318.66 | F20: =(E20-E8)/E8 -> 0.34956806
A21: 32020 | B21: =VLOOKUP(A21,'NFIB SBO Core Index'!A:B,2,FALSE) -> 103.745 | C21: =B21-B20 -> 1.26 | D21: =B21-B9 -> 4.9306 | E21: 329.79999 | F21: =(E21-E9)/E9 -> 0.30391807
A22: 32050 | B22: =VLOOKUP(A22,'NFIB SBO Core Index'!A:B,2,FALSE) -> 102.421 | C22: =B22-B21 -> -1.324 | D22: =B22-B10 -> 3.8349 | E22: 321.82999 | F22: =(E22-E10)/E10 -> 0.39127606
A23: 32081 | B23: =VLOOKUP(A23,'NFIB SBO Core Index'!A:B,2,FALSE) -> 101.59 | C23: =B23-B22 -> -0.831 | D23: =B23-B11 -> 2.8304 | E23: 251.78999 | F23: =(E23-E11)/E11 -> 0.032010809
A24: 32111 | B24: =VLOOKUP(A24,'NFIB SBO Core Index'!A:B,2,FALSE) -> 98.6318 | C24: =B24-B23 -> -2.9582 | D24: =B24-B12 -> 1.0958 | E24: 230.3 | F24: =(E24-E12)/E12 -> -0.075916852
A25: 32142 | B25: =VLOOKUP(A25,'NFIB SBO Core Index'!A:B,2,FALSE) -> 100.029 | C25: =B25-B24 -> 1.3972 | D25: =B25-B13 -> -0.639 | E25: 247.08 | F25: =(E25-E13)/E13 -> 0.02027503
... A421: 44196 | B421: =VLOOKUP(A421,'NFIB SBO Core Index'!A:B,2,FALSE) -> 95.708 | C421: =B421-B420 -> -5.479 | D421: =B421-B409 -> -6.575 | E421: 3756.0701 | F421: =(E421-E409)/E409 -> 0.16258923

Sheet SBO_Leading_vs_GDP
A1: Date | B1: SBO - Leading Index | C1: SBO - Leading Index MoM | D1: SBO - Leading Index YoY | E1: US Real GDP, Billions 2012 USD, Seasonally Adjusted | F1: GDP YoY %
A2: ='NFIB SBO Core Index'!A2 -> 31443 | B2: =AVERAGE('Expansion Plans'!B2+'Employment Plans'!B2+'Inventory Plans'!B2+'Economic Expectations'!B2+'Real Sales Expectations'!B2) -> 57
A3: ='NFIB SBO Core Index'!A3 -> 31471 | B3: =AVERAGE('Expansion Plans'!B3+'Employment Plans'!B3+'Inventory Plans'!B3+'Economic Expectations'!B3+'Real Sales Expectations'!B3) -> 56 | C3: =B3-B2 -> -1
A4: ='NFIB SBO Core Index'!A4 -> 31502 | B4: =AVERAGE('Expansion Plans'!B4+'Employment Plans'!B4+'Inventory Plans'!B4+'Economic Expectations'!B4+'Real Sales Expectations'!B4) -> 78 | C4: =B4-B3 -> 22 | E4: 8148.603
A5: ='NFIB SBO Core Index'!A5 -> 31532 | B5: =AVERAGE('Expansion Plans'!B5+'Employment Plans'!B5+'Inventory Plans'!B5+'Economic Expectations'!B5+'Real Sales Expectations'!B5) -> 70 | C5: =B5-B4 -> -8
A6: ='NFIB SBO Core Index'!A6 -> 31563 | B6: =AVERAGE('Expansion Plans'!B6+'Employment Plans'!B6+'Inventory Plans'!B6+'Economic Expectations'!B6+'Real Sales Expectations'!B6) -> 67 | C6: =B6-B5 -> -3
A7: ='NFIB SBO Core Index'!A7 -> 31593 | B7: =AVERAGE('Expansion Plans'!B7+'Employment Plans'!B7+'Inventory Plans'!B7+'Economic Expectations'!B7+'Real Sales Expectations'!B7) -> 71 | C7: =B7-B6 -> 4 | E7: 8185.303
A8: ='NFIB SBO Core Index'!A8 -> 31624 | B8: =AVERAGE('Expansion Plans'!B8+'Employment Plans'!B8+'Inventory Plans'!B8+'Economic Expectations'!B8+'Real Sales Expectations'!B8) -> 50 | C8: =B8-B7 -> -21
A9: ='NFIB SBO Core Index'!A9 -> 31655 | B9: =AVERAGE('Expansion Plans'!B9+'Employment Plans'!B9+'Inventory Plans'!B9+'Economic Expectations'!B9+'Real Sales Expectations'!B9) -> 39 | C9: =B9-B8 -> -11
A10: ='NFIB SBO Core Index'!A10 -> 31685 | B10: =AVERAGE('Expansion Plans'!B10+'Employment Plans'!B10+'Inventory Plans'!B10+'Economic Expectations'!B10+'Real Sales Expectations'!B10) -> 36 | C10: =B10-B9 -> -3 | E10: 8263.639
A11: ='NFIB SBO Core Index'!A11 -> 31716 | B11: =AVERAGE('Expansion Plans'!B11+'Employment Plans'!B11+'Inventory Plans'!B11+'Economic Expectations'!B11+'Real Sales Expectations'!B11) -> 43 | C11: =B11-B10 -> 7
A12: ='NFIB SBO Core Index'!A12 -> 31746 | B12: =AVERAGE('Expansion Plans'!B12+'Employment Plans'!B12+'Inventory Plans'!B12+'Economic Expectations'!B12+'Real Sales Expectations'!B12) -> 27 | C12: =B12-B11 -> -16
A13: ='NFIB SBO Core Index'!A13 -> 31777 | B13: =AVERAGE('Expansion Plans'!B13+'Employment Plans'!B13+'Inventory Plans'!B13+'Economic Expectations'!B13+'Real Sales Expectations'!B13) -> 42 | C13: =B13-B12 -> 15 | E13: 8308.021
A14: ='NFIB SBO Core Index'!A14 -> 31808 | B14: =AVERAGE('Expansion Plans'!B14+'Employment Plans'!B14+'Inventory Plans'!B14+'Economic Expectations'!B14+'Real Sales Expectations'!B14) -> 46 | C14: =B14-B13 -> 4 | D14: =B14-B2 -> -11
A15: ='NFIB SBO Core Index'!A15 -> 31836 | B15: =AVERAGE('Expansion Plans'!B15+'Employment Plans'!B15+'Inventory Plans'!B15+'Economic Expectations'!B15+'Real Sales Expectations'!B15) -> 54 | C15: =B15-B14 -> 8 | D15: =B15-B3 -> -2
A16: ='NFIB SBO Core Index'!A16 -> 31867 | B16: =AVERAGE('Expansion Plans'!B16+'Employment Plans'!B16+'Inventory Plans'!B16+'Economic Expectations'!B16+'Real Sales Expectations'!B16) -> 54 | C16: =B16-B15 -> 0 | D16: =B16-B4 -> -24 | E16: 8369.93 | F16: =(E16-E4)/E4 -> 0.027161343
A17: ='NFIB SBO Core Index'!A17 -> 31897 | B17: =AVERAGE('Expansion Plans'!B17+'Employment Plans'!B17+'Inventory Plans'!B17+'Economic Expectations'!B17+'Real Sales Expectations'!B17) -> 45 | C17: =B17-B16 -> -9 | D17: =B17-B5 -> -25
A18: ='NFIB SBO Core Index'!A18 -> 31928 | B18: =AVERAGE('Expansion Plans'!B18+'Employment Plans'!B18+'Inventory Plans'!B18+'Economic Expectations'!B18+'Real Sales Expectations'!B18) -> 35 | C18: =B18-B17 -> -10 | D18: =B18-B6 -> -32
A19: ='NFIB SBO Core Index'!A19 -> 31958 | B19: =AVERAGE('Expansion Plans'!B19+'Employment Plans'!B19+'Inventory Plans'!B19+'Economic Expectations'!B19+'Real Sales Expectations'!B19) -> 54 | C19: =B19-B18 -> 19 | D19: =B19-B7 -> -17 | E19: 8460.233 | F19: =(E19-E7)/E7 -> 0.03358825
A20: ='NFIB SBO Core Index'!A20 -> 31989 | B20: =AVERAGE('Expansion Plans'!B20+'Employment Plans'!B20+'Inventory Plans'!B20+'Economic Expectations'!B20+'Real Sales Expectations'!B20) -> 54 | C20: =B20-B19 -> 0 | D20: =B20-B8 -> 4
A21: ='NFIB SBO Core Index'!A21 -> 32020 | B21: =AVERAGE('Expansion Plans'!B21+'Employment Plans'!B21+'Inventory Plans'!B21+'Economic Expectations'!B21+'Real Sales Expectations'!B21) -> 75 | C21: =B21-B20 -> 21 | D21: =B21-B9 -> 36
A22: ='NFIB SBO Core Index'!A22 -> 32050 | B22: =AVERAGE('Expansion Plans'!B22+'Employment Plans'!B22+'Inventory Plans'!B22+'Economic Expectations'!B22+'Real Sales Expectations'!B22) -> 57 | C22: =B22-B21 -> -18 | D22: =B22-B10 -> 21 | E22: 8533.635 | F22: =(E22-E10)/E10 -> 0.032672773
A23: ='NFIB SBO Core Index'!A23 -> 32081 | B23: =AVERAGE('Expansion Plans'!B23+'Employment Plans'!B23+'Inventory Plans'!B23+'Economic Expectations'!B23+'Real Sales Expectations'!B23) -> 52 | C23: =B23-B22 -> -5 | D23: =B23-B11 -> 9
A24: ='NFIB SBO Core Index'!A24 -> 32111 | B24: =AVERAGE('Expansion Plans'!B24+'Employment Plans'!B24+'Inventory Plans'!B24+'Economic Expectations'!B24+'Real Sales Expectations'!B24) -> 26 | C24: =B24-B23 -> -26 | D24: =B24-B12 -> -1
A25: ='NFIB SBO Core Index'!A25 -> 32142 | B25: =AVERAGE('Expansion Plans'!B25+'Employment Plans'!B25+'Inventory Plans'!B25+'Economic Expectations'!B25+'Real Sales Expectations'!B25) -> 24 | C25: =B25-B24 -> -2 | D25: =B25-B13 -> -18 | E25: 8680.162 | F25: =(E25-E13)/E13 -> 0.044792978
A26: ='NFIB SBO Core Index'!A26 -> 32173 | B26: =AVERAGE('Expansion Plans'!B26+'Employment Plans'!B26+'Inventory Plans'!B26+'Economic Expectations'!B26+'Real Sales Expectations'!B26) -> 35 | C26: =B26-B25 -> 11 | D26: =B26-B14 -> -11
A27: ='NFIB SBO Core Index'!A27 -> 32202 | B27: =AVERAGE('Expansion Plans'!B27+'Employment Plans'!B27+'Inventory Plans'!B27+'Economic Expectations'!B27+'Real Sales Expectations'!B27) -> 28 | C27: =B27-B26 -> -7 | D27: =B27-B15 -> -26
A28: ='NFIB SBO Core Index'!A28 -> 32233 | B28: =AVERAGE('Expansion Plans'!B28+'Employment Plans'!B28+'Inventory Plans'!B28+'Economic Expectations'!B28+'Real Sales Expectations'!B28) -> 52 | C28: =B28-B27 -> 24 | D28: =B28-B16 -> -2 | E28: 8725.006 | F28: =(E28-E16)/E16 -> 0.042422816
A29: ='NFIB SBO Core Index'!A29 -> 32263 | B29: =AVERAGE('Expansion Plans'!B29+'Employment Plans'!B29+'Inventory Plans'!B29+'Economic Expectations'!B29+'Real Sales Expectations'!B29) -> 47 | C29: =B29-B28 -> -5 | D29: =B29-B17 -> 2
A30: ='NFIB SBO Core Index'!A30 -> 32294 | B30: =AVERAGE('Expansion Plans'!B30+'Employment Plans'!B30+'Inventory Plans'!B30+'Economic Expectations'!B30+'Real Sales Expectations'!B30) -> 33 | C30: =B30-B29 -> -14 | D30: =B30-B18 -> -2
A31: ='NFIB SBO Core Index'!A31 -> 32324 | B31: =AVERAGE('Expansion Plans'!B31+'Employment Plans'!B31+'Inventory Plans'!B31+'Economic Expectations'!B31+'Real Sales Expectations'!B31) -> 46 | C31: =B31-B30 -> 13 | D31: =B31-B19 -> -8 | E31: 8839.641 | F31: =(E31-E19)/E19 -> 0.044846046
A32: ='NFIB SBO Core Index'!A32 -> 32355 | B32: =AVERAGE('Expansion Plans'!B32+'Employment Plans'!B32+'Inventory Plans'!B32+'Economic Expectations'!B32+'Real Sales Expectations'!B32) -> 34 | C32: =B32-B31 -> -12 | D32: =B32-B20 -> -20
A33: ='NFIB SBO Core Index'!A33 -> 32386 | B33: =AVERAGE('Expansion Plans'!B33+'Employment Plans'!B33+'Inventory Plans'!B33+'Economic Expectations'!B33+'Real Sales Expectations'!B33) -> 50 | C33: =B33-B32 -> 16 | D33: =B33-B21 -> -25
A34: ='NFIB SBO Core Index'!A34 -> 32416 | B34: =AVERAGE('Expansion Plans'!B34+'Employment Plans'!B34+'Inventory Plans'!B34+'Economic Expectations'!B34+'Real Sales Expectations'!B34) -> 41 | C34: =B34-B33 -> -9 | D34: =B34-B22 -> -16 | E34: 8891.435 | F34: =(E34-E22)/E22 -> 0.041928205
A35: ='NFIB SBO Core Index'!A35 -> 32447 | B35: =AVERAGE('Expansion Plans'!B35+'Employment Plans'!B35+'Inventory Plans'!B35+'Economic Expectations'!B35+'Real Sales Expectations'!B35) -> 52 | C35: =B35-B34 -> 11 | D35: =B35-B23 -> 0
A36: ='NFIB SBO Core Index'!A36 -> 32477 | B36: =AVERAGE('Expansion Plans'!B36+'Employment Plans'!B36+'Inventory Plans'!B36+'Economic Expectations'!B36+'Real Sales Expectations'!B36) -> 47 | C36: =B36-B35 -> -5 | D36: =B36-B24 -> 21
A37: ='NFIB SBO Core Index'!A37 -> 32508 | B37: =AVERAGE('Expansion Plans'!B37+'Employment Plans'!B37+'Inventory Plans'!B37+'Economic Expectations'!B37+'Real Sales Expectations'!B37) -> 39 | C37: =B37-B36 -> -8 | D37: =B37-B25 -> 15 | E37: 9009.913 | F37: =(E37-E25)/E25 -> 0.037989038
A38: ='NFIB SBO Core Index'!A38 -> 32539 | B38: =AVERAGE('Expansion Plans'!B38+'Employment Plans'!B38+'Inventory Plans'!B38+'Economic Expectations'!B38+'Real Sales Expectations'!B38) -> 42 | C38: =B38-B37 -> 3 | D38: =B38-B26 -> 7
A39: ='NFIB SBO Core Index'!A39 -> 32567 | B39: =AVERAGE('Expansion Plans'!B39+'Employment Plans'!B39+'Inventory Plans'!B39+'Economic Expectations'!B39+'Real Sales Expectations'!B39) -> 53 | C39: =B39-B38 -> 11 | D39: =B39-B27 -> 25
A40: ='NFIB SBO Core Index'!A40 -> 32598 | B40: =AVERAGE('Expansion Plans'!B40+'Employment Plans'!B40+'Inventory Plans'!B40+'Economic Expectations'!B40+'Real Sales Expectations'!B40) -> 40 | C40: =B40-B39 -> -13 | D40: =B40-B28 -> -12 | E40: 9101.508 | F40: =(E40-E28)/E28 -> 0.043152062
...

Sheet SBO_Leading_vs_SP500
A1: Date | B1: SBO - Leading Index | C1: SBO - Leading Index MoM | D1: SBO - Leading Index YoY | E1: S&P 500 Index | F1: S&P 500 Index YoY %
A2: 31443 | B2: =AVERAGE('Expansion Plans'!B2+'Employment Plans'!B2+'Inventory Plans'!B2+'Economic Expectations'!B2+'Real Sales Expectations'!B2) -> 57 | E2: 211.78
A3: 31471 | B3: =AVERAGE('Expansion Plans'!B3+'Employment Plans'!B3+'Inventory Plans'!B3+'Economic Expectations'!B3+'Real Sales Expectations'!B3) -> 56 | C3: =B3-B2 -> -1 | E3: 226.92
A4: 31502 | B4: =AVERAGE('Expansion Plans'!B4+'Employment Plans'!B4+'Inventory Plans'!B4+'Economic Expectations'!B4+'Real Sales Expectations'!B4) -> 78 | C4: =B4-B3 -> 22 | E4: 238.89999
A5: 31532 | B5: =AVERAGE('Expansion Plans'!B5+'Employment Plans'!B5+'Inventory Plans'!B5+'Economic Expectations'!B5+'Real Sales Expectations'!B5) -> 70 | C5: =B5-B4 -> -8 | E5: 235.52
A6: 31563 | B6: =AVERAGE('Expansion Plans'!B6+'Employment Plans'!B6+'Inventory Plans'!B6+'Economic Expectations'!B6+'Real Sales Expectations'!B6) -> 67 | C6: =B6-B5 -> -3 | E6: 247.35001
A7: 31593 | B7: =AVERAGE('Expansion Plans'!B7+'Employment Plans'!B7+'Inventory Plans'!B7+'Economic Expectations'!B7+'Real Sales Expectations'!B7) -> 71 | C7: =B7-B6 -> 4 | E7: 250.84
A8: 31624 | B8: =AVERAGE('Expansion Plans'!B8+'Employment Plans'!B8+'Inventory Plans'!B8+'Economic Expectations'!B8+'Real Sales Expectations'!B8) -> 50 | C8: =B8-B7 -> -21 | E8: 236.11999
A9: 31655 | B9: =AVERAGE('Expansion Plans'!B9+'Employment Plans'!B9+'Inventory Plans'!B9+'Economic Expectations'!B9+'Real Sales Expectations'!B9) -> 39 | C9: =B9-B8 -> -11 | E9: 252.92999
A10: 31685 | B10: =AVERAGE('Expansion Plans'!B10+'Employment Plans'!B10+'Inventory Plans'!B10+'Economic Expectations'!B10+'Real Sales Expectations'!B10) -> 36 | C10: =B10-B9 -> -3 | E10: 231.32001
A11: 31716 | B11: =AVERAGE('Expansion Plans'!B11+'Employment Plans'!B11+'Inventory Plans'!B11+'Economic Expectations'!B11+'Real Sales Expectations'!B11) -> 43 | C11: =B11-B10 -> 7 | E11: 243.98
A12: 31746 | B12: =AVERAGE('Expansion Plans'!B12+'Employment Plans'!B12+'Inventory Plans'!B12+'Economic Expectations'!B12+'Real Sales Expectations'!B12) -> 27 | C12: =B12-B11 -> -16 | E12: 249.22
A13: 31777 | B13: =AVERAGE('Expansion Plans'!B13+'Employment Plans'!B13+'Inventory Plans'!B13+'Economic Expectations'!B13+'Real Sales Expectations'!B13) -> 42 | C13: =B13-B12 -> 15 | E13: 242.17
A14: 31808 | B14: =AVERAGE('Expansion Plans'!B14+'Employment Plans'!B14+'Inventory Plans'!B14+'Economic Expectations'!B14+'Real Sales Expectations'!B14) -> 46 | C14: =B14-B13 -> 4 | D14: =B14-B2 -> -11 | E14: 274.07999 | F14: =(E14-E2)/E2 -> 0.29417314
A15: 31836 | B15: =AVERAGE('Expansion Plans'!B15+'Employment Plans'!B15+'Inventory Plans'!B15+'Economic Expectations'!B15+'Real Sales Expectations'!B15) -> 54 | C15: =B15-B14 -> 8 | D15: =B15-B3 -> -2 | E15: 284.20001 | F15: =(E15-E3)/E3 -> 0.25242383
A16: 31867 | B16: =AVERAGE('Expansion Plans'!B16+'Employment Plans'!B16+'Inventory Plans'!B16+'Economic Expectations'!B16+'Real Sales Expectations'!B16) -> 54 | C16: =B16-B15 -> 0 | D16: =B16-B4 -> -24 | E16: 291.70001 | F16: =(E16-E4)/E4 -> 0.22101306
A17: 31897 | B17: =AVERAGE('Expansion Plans'!B17+'Employment Plans'!B17+'Inventory Plans'!B17+'Economic Expectations'!B17+'Real Sales Expectations'!B17) -> 45 | C17: =B17-B16 -> -9 | D17: =B17-B5 -> -25 | E17: 288.35998 | F17: =(E17-E5)/E5 -> 0.22435454
A18: 31928 | B18: =AVERAGE('Expansion Plans'!B18+'Employment Plans'!B18+'Inventory Plans'!B18+'Economic Expectations'!B18+'Real Sales Expectations'!B18) -> 35 | C18: =B18-B17 -> -10 | D18: =B18-B6 -> -32 | E18: 290.10001 | F18: =(E18-E6)/E6 -> 0.17283202
A19: 31958 | B19: =AVERAGE('Expansion Plans'!B19+'Employment Plans'!B19+'Inventory Plans'!B19+'Economic Expectations'!B19+'Real Sales Expectations'!B19) -> 54 | C19: =B19-B18 -> 19 | D19: =B19-B7 -> -17 | E19: 304 | F19: =(E19-E7)/E7 -> 0.21192794
A20: 31989 | B20: =AVERAGE('Expansion Plans'!B20+'Employment Plans'!B20+'Inventory Plans'!B20+'Economic Expectations'!B20+'Real Sales Expectations'!B20) -> 54 | C20: =B20-B19 -> 0 | D20: =B20-B8 -> 4 | E20: 318.66 | F20: =(E20-E8)/E8 -> 0.34956806
A21: 32020 | B21: =AVERAGE('Expansion Plans'!B21+'Employment Plans'!B21+'Inventory Plans'!B21+'Economic Expectations'!B21+'Real Sales Expectations'!B21) -> 75 | C21: =B21-B20 -> 21 | D21: =B21-B9 -> 36 | E21: 329.79999 | F21: =(E21-E9)/E9 -> 0.30391807
A22: 32050 | B22: =AVERAGE('Expansion Plans'!B22+'Employment Plans'!B22+'Inventory Plans'!B22+'Economic Expectations'!B22+'Real Sales Expectations'!B22) -> 57 | C22: =B22-B21 -> -18 | D22: =B22-B10 -> 21 | E22: 321.82999 | F22: =(E22-E10)/E10 -> 0.39127606
A23: 32081 | B23: =AVERAGE('Expansion Plans'!B23+'Employment Plans'!B23+'Inventory Plans'!B23+'Economic Expectations'!B23+'Real Sales Expectations'!B23) -> 52 | C23: =B23-B22 -> -5 | D23: =B23-B11 -> 9 | E23: 251.78999 | F23: =(E23-E11)/E11 -> 0.032010809
A24: 32111 | B24: =AVERAGE('Expansion Plans'!B24+'Employment Plans'!B24+'Inventory Plans'!B24+'Economic Expectations'!B24+'Real Sales Expectations'!B24) -> 26 | C24: =B24-B23 -> -26 | D24: =B24-B12 -> -1 | E24: 230.3 | F24: =(E24-E12)/E12 -> -0.075916852
A25: 32142 | B25: =AVERAGE('Expansion Plans'!B25+'Employment Plans'!B25+'Inventory Plans'!B25+'Economic Expectations'!B25+'Real Sales Expectations'!B25) -> 24 | C25: =B25-B24 -> -2 | D25: =B25-B13 -> -18 | E25: 247.08 | F25: =(E25-E13)/E13 -> 0.02027503
... A421: 44196 | B421: =AVERAGE('Expansion Plans'!B421+'Employment Plans'!B421+'Inventory Plans'!B421+'Economic Expectations'!B421+'Real Sales Expectations'!B421) -> -5 | C421: =B421-B420 -> -57 | D421: =B421-B409 -> -80 | E421: 3756.0701 | F421: =(E421-E409)/E409 -> 0.16258923

Sheet Expansion Plans
B1: Now a Good Time to Expand | C1: =B1&" - 3mma" -> Now a Good Time to Expand - 3mma | D1: =B1&" YoY" -> Now a Good Time to Expand YoY | E1: =C1&" YoY" -> Now a Good Time to Expand - 3mma YoY
A2: 31443 | B2: 20 | G2: =B1&" - NFIB" -> Now a Good Time to Expand - NFIB | U2: =D1&" - NFIB" -> Now a Good Time to Expand YoY - NFIB
A3: 31471 | B3: 19
A4: 31502 | B4: 26 | C4: =AVERAGE(B2:B4) -> 21.666667
A5: 31532 | B5: 27 | C5: =AVERAGE(B3:B5) -> 24
A6: 31563 | B6: 26 | C6: =AVERAGE(B4:B6) -> 26.333333
A7: 31593 | B7: 23 | C7: =AVERAGE(B5:B7) -> 25.333333
A8: 31624 | B8: 20 | C8: =AVERAGE(B6:B8) -> 23
A9: 31655 | B9: 16 | C9: =AVERAGE(B7:B9) -> 19.666667
A10: 31685 | B10: 19 | C10: =AVERAGE(B8:B10) -> 18.333333
A11: 31716 | B11: 19 | C11: =AVERAGE(B9:B11) -> 18
A12: 31746 | B12: 16 | C12: =AVERAGE(B10:B12) -> 18
A13: 31777 | B13: 18 | C13: =AVERAGE(B11:B13) -> 17.666667
A14: 31808 | B14: 18 | C14: =AVERAGE(B12:B14) -> 17.333333 | D14: =B14-B2 -> -2
A15: 31836 | B15: 17 | C15: =AVERAGE(B13:B15) -> 17.666667 | D15: =B15-B3 -> -2
A16: 31867 | B16: 21 | C16: =AVERAGE(B14:B16) -> 18.666667 | D16: =B16-B4 -> -5 | E16: =C16-C4 -> -3
A17: 31897 | B17: 18 | C17: =AVERAGE(B15:B17) -> 18.666667 | D17: =B17-B5 -> -9 | E17: =C17-C5 -> -5.3333333
A18: 31928 | B18: 18 | C18: =AVERAGE(B16:B18) -> 19 | D18: =B18-B6 -> -8 | E18: =C18-C6 -> -7.3333333
A19: 31958 | B19: 20 | C19: =AVERAGE(B17:B19) -> 18.666667 | D19: =B19-B7 -> -3 | E19: =C19-C7 -> -6.6666667
A20: 31989 | B20: 19 | C20: =AVERAGE(B18:B20) -> 19 | D20: =B20-B8 -> -1 | E20: =C20-C8 -> -4
A21: 32020 | B21: 21 | C21: =AVERAGE(B19:B21) -> 20 | D21: =B21-B9 -> 5 | E21: =C21-C9 -> 0.33333333
A22: 32050 | B22: 21 | C22: =AVERAGE(B20:B22) -> 20.333333 | D22: =B22-B10 -> 2 | E22: =C22-C10 -> 2
A23: 32081 | B23: 18 | C23: =AVERAGE(B21:B23) -> 20 | D23: =B23-B11 -> -1 | E23: =C23-C11 -> 2
A24: 32111 | B24: 13 | C24: =AVERAGE(B22:B24) -> 17.333333 | D24: =B24-B12 -> -3 | E24: =C24-C12 -> -0.66666667
A25: 32142 | B25: 16 | C25: =AVERAGE(B23:B25) -> 15.666667 | D25: =B25-B13 -> -2 | E25: =C25-C13 -> -2
A26: 32173 | B26: 13 | C26: =AVERAGE(B24:B26) -> 14 | D26: =B26-B14 -> -5 | E26: =C26-C14 -> -3.3333333
A27: 32202 | B27: 15 | C27: =AVERAGE(B25:B27) -> 14.666667 | D27: =B27-B15 -> -2 | E27: =C27-C15 -> -3 | G27: =B1&" - NFIB - 2000-" -> Now a Good Time to Expand - NFIB - 2000- | U27: =D1&" - NFIB - 2000-" -> Now a Good Time to Expand YoY - NFIB - 2000-
A28: 32233 | B28: 18 | C28: =AVERAGE(B26:B28) -> 15.333333 | D28: =B28-B16 -> -3 | E28: =C28-C16 -> -3.3333333
A29: 32263 | B29: 20 | C29: =AVERAGE(B27:B29) -> 17.666667 | D29: =B29-B17 -> 2 | E29: =C29-C17 -> -1
A30: 32294 | B30: 19 | C30: =AVERAGE(B28:B30) -> 19 | D30: =B30-B18 -> 1 | E30: =C30-C18 -> 0
A31: 32324 | B31: 20 | C31: =AVERAGE(B29:B31) -> 19.666667 | D31: =B31-B19 -> 0 | E31: =C31-C19 -> 1
A32: 32355 | B32: 19 | C32: =AVERAGE(B30:B32) -> 19.333333 | D32: =B32-B20 -> 0 | E32: =C32-C20 -> 0.33333333
A33: 32386 | B33: 22 | C33: =AVERAGE(B31:B33) -> 20.333333 | D33: =B33-B21 -> 1 | E33: =C33-C21 -> 0.33333333
A34: 32416 | B34: 17 | C34: =AVERAGE(B32:B34) -> 19.333333 | D34: =B34-B22 -> -4 | E34: =C34-C22 -> -1
A35: 32447 | B35: 17 | C35: =AVERAGE(B33:B35) -> 18.666667 | D35: =B35-B23 -> -1 | E35: =C35-C23 -> -1.3333333
A36: 32477 | B36: 18 | C36: =AVERAGE(B34:B36) -> 17.333333 | D36: =B36-B24 -> 5 | E36: =C36-C24 -> 0
A37: 32508 | B37: 17 | C37: =AVERAGE(B35:B37) -> 17.333333 | D37: =B37-B25 -> 1 | E37: =C37-C25 -> 1.6666667
A38: 32539 | B38: 17 | C38: =AVERAGE(B36:B38) -> 17.333333 | D38: =B38-B26 -> 4 | E38: =C38-C26 -> 3.3333333
A39: 32567 | B39: 21 | C39: =AVERAGE(B37:B39) -> 18.333333 | D39: =B39-B27 -> 6 | E39: =C39-C27 -> 3.6666667
... A51: 32932 | B51: 12 | C51: =AVERAGE(B49:B51) -> 14.333333 | D51: =B51-B39 -> -9 | E51: =C51-C39 -> -4
...

Sheet Employment Plans
B1: Plans to Increase Employment | C1: =B1&" - 3mma" -> Plans to Increase Employment - 3mma | D1: =B1&" YoY" -> Plans to Increase Employment YoY | E1: =C1&" YoY" -> Plans to Increase Employment - 3mma YoY
A2: 31443 | B2: 9 | G2: =B1&" - NFIB" -> Plans to Increase Employment - NFIB | U2: =D1&" - NFIB" -> Plans to Increase Employment YoY - NFIB
A3: 31471 | B3: 7
A4: 31502 | B4: 13 | C4: =AVERAGE(B2:B4) -> 9.6666667
A5: 31532 | B5: 9 | C5: =AVERAGE(B3:B5) -> 9.6666667
A6: 31563 | B6: 9 | C6: =AVERAGE(B4:B6) -> 10.333333
A7: 31593 | B7: 10 | C7: =AVERAGE(B5:B7) -> 9.3333333
A8: 31624 | B8: 8 | C8: =AVERAGE(B6:B8) -> 9
A9: 31655 | B9: 5 | C9: =AVERAGE(B7:B9) -> 7.6666667
A10: 31685 | B10: 2 | C10: =AVERAGE(B8:B10) -> 5
A11: 31716 | B11: 7 | C11: =AVERAGE(B9:B11) -> 4.6666667
A12: 31746 | B12: 6 | C12: =AVERAGE(B10:B12) -> 5
A13: 31777 | B13: 9 | C13: =AVERAGE(B11:B13) -> 7.3333333
A14: 31808 | B14: 7 | C14: =AVERAGE(B12:B14) -> 7.3333333 | D14: =B14-B2 -> -2
A15: 31836 | B15: 7 | C15: =AVERAGE(B13:B15) -> 7.6666667 | D15: =B15-B3 -> 0
A16: 31867 | B16: 9 | C16: =AVERAGE(B14:B16) -> 7.6666667 | D16: =B16-B4 -> -4 | E16: =C16-C4 -> -2
A17: 31897 | B17: 10 | C17: =AVERAGE(B15:B17) -> 8.6666667 | D17: =B17-B5 -> 1 | E17: =C17-C5 -> -1
A18: 31928 | B18: 11 | C18: =AVERAGE(B16:B18) -> 10 | D18: =B18-B6 -> 2 | E18: =C18-C6 -> -0.33333333
A19: 31958 | B19: 11 | C19: =AVERAGE(B17:B19) -> 10.666667 | D19: =B19-B7 -> 1 | E19: =C19-C7 -> 1.3333333
A20: 31989 | B20: 10 | C20: =AVERAGE(B18:B20) -> 10.666667 | D20: =B20-B8 -> 2 | E20: =C20-C8 -> 1.6666667
A21: 32020 | B21: 14 | C21: =AVERAGE(B19:B21) -> 11.666667 | D21: =B21-B9 -> 9 | E21: =C21-C9 -> 4
A22: 32050 | B22: 11 | C22: =AVERAGE(B20:B22) -> 11.666667 | D22: =B22-B10 -> 9 | E22: =C22-C10 -> 6.6666667
A23: 32081 | B23: 10 | C23: =AVERAGE(B21:B23) -> 11.666667 | D23: =B23-B11 -> 3 | E23: =C23-C11 -> 7
A24: 32111 | B24: 9 | C24: =AVERAGE(B22:B24) -> 10 | D24: =B24-B12 -> 3 | E24: =C24-C12 -> 5
A25: 32142 | B25: 9 | C25: =AVERAGE(B23:B25) -> 9.3333333 | D25: =B25-B13 -> 0 | E25: =C25-C13 -> 2
A26: 32173 | B26: 12 | C26: =AVERAGE(B24:B26) -> 10 | D26: =B26-B14 -> 5 | E26: =C26-C14 -> 2.6666667
A27: 32202 | B27: 10 | C27: =AVERAGE(B25:B27) -> 10.333333 | D27: =B27-B15 -> 3 | E27: =C27-C15 -> 2.6666667 | G27: =B1&" - NFIB - 2000-" -> Plans to Increase Employment - NFIB - 2000- | U27: =D1&" - NFIB - 2000-" -> Plans to Increase Employment YoY - NFIB - 2000-
A28: 32233 | B28: 13 | C28: =AVERAGE(B26:B28) -> 11.666667 | D28: =B28-B16 -> 4 | E28: =C28-C16 -> 4
A29: 32263 | B29: 13 | C29: =AVERAGE(B27:B29) -> 12 | D29: =B29-B17 -> 3 | E29: =C29-C17 -> 3.3333333
A30: 32294 | B30: 11 | C30: =AVERAGE(B28:B30) -> 12.333333 | D30: =B30-B18 -> 0 | E30: =C30-C18 -> 2.3333333
A31: 32324 | B31: 12 | C31: =AVERAGE(B29:B31) -> 12 | D31: =B31-B19 -> 1 | E31: =C31-C19 -> 1.3333333
A32: 32355 | B32: 10 | C32: =AVERAGE(B30:B32) -> 11 | D32: =B32-B20 -> 0 | E32: =C32-C20 -> 0.33333333
A33: 32386 | B33: 12 | C33: =AVERAGE(B31:B33) -> 11.333333 | D33: =B33-B21 -> -2 | E33: =C33-C21 -> -0.33333333
A34: 32416 | B34: 14 | C34: =AVERAGE(B32:B34) -> 12 | D34: =B34-B22 -> 3 | E34: =C34-C22 -> 0.33333333
A35: 32447 | B35: 13 | C35: =AVERAGE(B33:B35) -> 13 | D35: =B35-B23 -> 3 | E35: =C35-C23 -> 1.3333333
A36: 32477 | B36: 11 | C36: =AVERAGE(B34:B36) -> 12.666667 | D36: =B36-B24 -> 2 | E36: =C36-C24 -> 2.6666667
A37: 32508 | B37: 11 | C37: =AVERAGE(B35:B37) -> 11.666667 | D37: =B37-B25 -> 2 | E37: =C37-C25 -> 2.3333333
A38: 32539 | B38: 11 | C38: =AVERAGE(B36:B38) -> 11 | D38: =B38-B26 -> -1 | E38: =C38-C26 -> 1
A39: 32567 | B39: 13 | C39: =AVERAGE(B37:B39) -> 11.666667 | D39: =B39-B27 -> 3 | E39: =C39-C27 -> 1.3333333
... A51: 32932 | B51: 11 | C51: =AVERAGE(B49:B51) -> 9.3333333 | D51: =B51-B39 -> -2 | E51: =C51-C39 -> -2.3333333
...

Sheet Inventory Plans
B1: Plans to Increase Inventories | C1: =B1&" - 3mma" -> Plans to Increase Inventories - 3mma | D1: =B1&" YoY" -> Plans to Increase Inventories YoY | E1: =C1&" YoY" -> Plans to Increase Inventories - 3mma YoY
A2: 31443 | B2: 4 | G2: =B1&" - NFIB" -> Plans to Increase Inventories - NFIB | U2: =D1&" - NFIB" -> Plans to Increase Inventories YoY - NFIB
A3: 31471 | B3: 4
A4: 31502 | B4: 3 | C4: =AVERAGE(B2:B4) -> 3.6666667
A5: 31532 | B5: 2 | C5: =AVERAGE(B3:B5) -> 3
A6: 31563 | B6: 6 | C6: =AVERAGE(B4:B6) -> 3.6666667
A7: 31593 | B7: 4 | C7: =AVERAGE(B5:B7) -> 4
A8: 31624 | B8: 4 | C8: =AVERAGE(B6:B8) -> 4.6666667
A9: 31655 | B9: -2 | C9: =AVERAGE(B7:B9) -> 2
A10: 31685 | B10: 3 | C10: =AVERAGE(B8:B10) -> 1.6666667
A11: 31716 | B11: 3 | C11: =AVERAGE(B9:B11) -> 1.3333333
A12: 31746 | B12: -5 | C12: =AVERAGE(B10:B12) -> 0.33333333
A13: 31777 | B13: 5 | C13: =AVERAGE(B11:B13) -> 1
A14: 31808 | B14: 5 | C14: =AVERAGE(B12:B14) -> 1.6666667 | D14: =B14-B2 -> 1
A15: 31836 | B15: 6 | C15: =AVERAGE(B13:B15) -> 5.3333333 | D15: =B15-B3 -> 2
A16: 31867 | B16: 4 | C16: =AVERAGE(B14:B16) -> 5 | D16: =B16-B4 -> 1 | E16: =C16-C4 -> 1.3333333
A17: 31897 | B17: 5 | C17: =AVERAGE(B15:B17) -> 5 | D17: =B17-B5 -> 3 | E17: =C17-C5 -> 2
A18: 31928 | B18: 4 | C18: =AVERAGE(B16:B18) -> 4.3333333 | D18: =B18-B6 -> -2 | E18: =C18-C6 -> 0.66666667
A19: 31958 | B19: 5 | C19: =AVERAGE(B17:B19) -> 4.6666667 | D19: =B19-B7 -> 1 | E19: =C19-C7 -> 0.66666667
A20: 31989 | B20: 5 | C20: =AVERAGE(B18:B20) -> 4.6666667 | D20: =B20-B8 -> 1 | E20: =C20-C8 -> 0
A21: 32020 | B21: 8 | C21: =AVERAGE(B19:B21) -> 6 | D21: =B21-B9 -> 10 | E21: =C21-C9 -> 4
A22: 32050 | B22: 7 | C22: =AVERAGE(B20:B22) -> 6.6666667 | D22: =B22-B10 -> 4 | E22: =C22-C10 -> 5
A23: 32081 | B23: 6 | C23: =AVERAGE(B21:B23) -> 7 | D23: =B23-B11 -> 3 | E23: =C23-C11 -> 5.6666667
A24: 32111 | B24: 2 | C24: =AVERAGE(B22:B24) -> 5 | D24: =B24-B12 -> 7 | E24: =C24-C12 -> 4.6666667
A25: 32142 | B25: 7 | C25: =AVERAGE(B23:B25) -> 5 | D25: =B25-B13 -> 2 | E25: =C25-C13 -> 4
A26: 32173 | B26: 8 | C26: =AVERAGE(B24:B26) -> 5.6666667 | D26: =B26-B14 -> 3 | E26: =C26-C14 -> 4
A27: 32202 | B27: 3 | C27: =AVERAGE(B25:B27) -> 6 | D27: =B27-B15 -> -3 | E27: =C27-C15 -> 0.66666667 | G27: =B1&" - NFIB - 2000-" -> Plans to Increase Inventories - NFIB - 2000- | U27: =D1&" - NFIB - 2000-" -> Plans to Increase Inventories YoY - NFIB - 2000-
A28: 32233 | B28: 9 | C28: =AVERAGE(B26:B28) -> 6.6666667 | D28: =B28-B16 -> 5 | E28: =C28-C16 -> 1.6666667
A29: 32263 | B29: 4 | C29: =AVERAGE(B27:B29) -> 5.3333333 | D29: =B29-B17 -> -1 | E29: =C29-C17 -> 0.33333333
A30: 32294 | B30: 3 | C30: =AVERAGE(B28:B30) -> 5.3333333 | D30: =B30-B18 -> -1 | E30: =C30-C18 -> 1
A31: 32324 | B31: 6 | C31: =AVERAGE(B29:B31) -> 4.3333333 | D31: =B31-B19 -> 1 | E31: =C31-C19 -> -0.33333333
A32: 32355 | B32: 3 | C32: =AVERAGE(B30:B32) -> 4 | D32: =B32-B20 -> -2 | E32: =C32-C20 -> -0.66666667
A33: 32386 | B33: 6 | C33: =AVERAGE(B31:B33) -> 5 | D33: =B33-B21 -> -2 | E33: =C33-C21 -> -1
A34: 32416 | B34: 6 | C34: =AVERAGE(B32:B34) -> 5 | D34: =B34-B22 -> -1 | E34: =C34-C22 -> -1.6666667
A35: 32447 | B35: 4 | C35: =AVERAGE(B33:B35) -> 5.3333333 | D35: =B35-B23 -> -2 | E35: =C35-C23 -> -1.6666667
A36: 32477 | B36: 2 | C36: =AVERAGE(B34:B36) -> 4 | D36: =B36-B24 -> 0 | E36: =C36-C24 -> -1
A37: 32508 | B37: 3 | C37: =AVERAGE(B35:B37) -> 3 | D37: =B37-B25 -> -4 | E37: =C37-C25 -> -2
A38: 32539 | B38: 6 | C38: =AVERAGE(B36:B38) -> 3.6666667 | D38: =B38-B26 -> -2 | E38: =C38-C26 -> -2
A39: 32567 | B39: 9 | C39: =AVERAGE(B37:B39) -> 6 | D39: =B39-B27 -> 6 | E39: =C39-C27 -> 0
... A51: 32932 | B51: 6 | C51: =AVERAGE(B49:B51) -> 4.3333333 | D51: =B51-B39 -> -3 | E51: =C51-C39 -> -1.6666667
...

Sheet Economic Expectations
B1: Expect Economy to Improve | C1: =B1&" - 3mma" -> Expect Economy to Improve - 3mma | D1: =B1&" YoY" -> Expect Economy to Improve YoY | E1: =C1&" YoY" -> Expect Economy to Improve - 3mma YoY
A2: 31443 | B2: 12 | G2: =B1&" - NFIB" -> Expect Economy to Improve - NFIB | U2: =D1&" - NFIB" -> Expect Economy to Improve YoY - NFIB
A3: 31471 | B3: 13
A4: 31502 | B4: 18 | C4: =AVERAGE(B2:B4) -> 14.333333
A5: 31532 | B5: 16 | C5: =AVERAGE(B3:B5) -> 15.666667
A6: 31563 | B6: 13 | C6: =AVERAGE(B4:B6) -> 15.666667
A7: 31593 | B7: 17 | C7: =AVERAGE(B5:B7) -> 15.333333
A8: 31624 | B8: 9 | C8: =AVERAGE(B6:B8) -> 13
A9: 31655 | B9: 10 | C9: =AVERAGE(B7:B9) -> 12
A10: 31685 | B10: 6 | C10: =AVERAGE(B8:B10) -> 8.3333333
A11: 31716 | B11: 7 | C11: =AVERAGE(B9:B11) -> 7.6666667
A12: 31746 | B12: 5 | C12: =AVERAGE(B10:B12) -> 6
A13: 31777 | B13: 5 | C13: =AVERAGE(B11:B13) -> 5.6666667
A14: 31808 | B14: 8 | C14: =AVERAGE(B12:B14) -> 6 | D14: =B14-B2 -> -4
A15: 31836 | B15: 12 | C15: =AVERAGE(B13:B15) -> 8.3333333 | D15: =B15-B3 -> -1
A16: 31867 | B16: 10 | C16: =AVERAGE(B14:B16) -> 10 | D16: =B16-B4 -> -8 | E16: =C16-C4 -> -4.3333333
A17: 31897 | B17: 6 | C17: =AVERAGE(B15:B17) -> 9.3333333 | D17: =B17-B5 -> -10 | E17: =C17-C5 -> -6.3333333
A18: 31928 | B18: 1 | C18: =AVERAGE(B16:B18) -> 5.6666667 | D18: =B18-B6 -> -12 | E18: =C18-C6 -> -10
A19: 31958 | B19: 9 | C19: =AVERAGE(B17:B19) -> 5.3333333 | D19: =B19-B7 -> -8 | E19: =C19-C7 -> -10
A20: 31989 | B20: 10 | C20: =AVERAGE(B18:B20) -> 6.6666667 | D20: =B20-B8 -> 1 | E20: =C20-C8 -> -6.3333333
A21: 32020 | B21: 16 | C21: =AVERAGE(B19:B21) -> 11.666667 | D21: =B21-B9 -> 6 | E21: =C21-C9 -> -0.33333333
A22: 32050 | B22: 9 | C22: =AVERAGE(B20:B22) -> 11.666667 | D22: =B22-B10 -> 3 | E22: =C22-C10 -> 3.3333333
A23: 32081 | B23: 9 | C23: =AVERAGE(B21:B23) -> 11.333333 | D23: =B23-B11 -> 2 | E23: =C23-C11 -> 3.6666667
A24: 32111 | B24: 1 | C24: =AVERAGE(B22:B24) -> 6.3333333 | D24: =B24-B12 -> -4 | E24: =C24-C12 -> 0.33333333
A25: 32142 | B25: -4 | C25: =AVERAGE(B23:B25) -> 2 | D25: =B25-B13 -> -9 | E25: =C25-C13 -> -3.6666667
A26: 32173 | B26: 1 | C26: =AVERAGE(B24:B26) -> -0.66666667 | D26: =B26-B14 -> -7 | E26: =C26-C14 -> -6.6666667
A27: 32202 | B27: 0 | C27: =AVERAGE(B25:B27) -> -1 | D27: =B27-B15 -> -12 | E27: =C27-C15 -> -9.3333333 | G27: =B1&" - NFIB - 2000-" -> Expect Economy to Improve - NFIB - 2000- | U27: =D1&" - NFIB - 2000-" -> Expect Economy to Improve YoY - NFIB - 2000-
A28: 32233 | B28: 6 | C28: =AVERAGE(B26:B28) -> 2.3333333 | D28: =B28-B16 -> -4 | E28: =C28-C16 -> -7.6666667
A29: 32263 | B29: 5 | C29: =AVERAGE(B27:B29) -> 3.6666667 | D29: =B29-B17 -> -1 | E29: =C29-C17 -> -5.6666667
A30: 32294 | B30: 0 | C30: =AVERAGE(B28:B30) -> 3.6666667 | D30: =B30-B18 -> -1 | E30: =C30-C18 -> -2
A31: 32324 | B31: 4 | C31: =AVERAGE(B29:B31) -> 3 | D31: =B31-B19 -> -5 | E31: =C31-C19 -> -2.3333333
A32: 32355 | B32: 1 | C32: =AVERAGE(B30:B32) -> 1.6666667 | D32: =B32-B20 -> -9 | E32: =C32-C20 -> -5
A33: 32386 | B33: 5 | C33: =AVERAGE(B31:B33) -> 3.3333333 | D33: =B33-B21 -> -11 | E33: =C33-C21 -> -8.3333333
A34: 32416 | B34: 2 | C34: =AVERAGE(B32:B34) -> 2.6666667 | D34: =B34-B22 -> -7 | E34: =C34-C22 -> -9
A35: 32447 | B35: 9 | C35: =AVERAGE(B33:B35) -> 5.3333333 | D35: =B35-B23 -> 0 | E35: =C35-C23 -> -6
A36: 32477 | B36: 8 | C36: =AVERAGE(B34:B36) -> 6.3333333 | D36: =B36-B24 -> 7 | E36: =C36-C24 -> 0
A37: 32508 | B37: 4 | C37: =AVERAGE(B35:B37) -> 7 | D37: =B37-B25 -> 8 | E37: =C37-C25 -> 5
A38: 32539 | B38: 4 | C38: =AVERAGE(B36:B38) -> 5.3333333 | D38: =B38-B26 -> 3 | E38: =C38-C26 -> 6
A39: 32567 | B39: 5 | C39: =AVERAGE(B37:B39) -> 4.3333333 | D39: =B39-B27 -> 5 | E39: =C39-C27 -> 5.3333333
... A51: 32932 | B51: 3 | C51: =AVERAGE(B49:B51) -> 4.3333333 | D51: =B51-B39 -> -2 | E51: =C51-C39 -> 0
...

Sheet Real Sales Expectations
B1: Expect Real Sales to Improve | C1: =B1&" - 3mma" -> Expect Real Sales to Improve - 3mma | D1: =B1&" YoY" -> Expect Real Sales to Improve YoY | E1: =C1&" YoY" -> Expect Real Sales to Improve - 3mma YoY
A2: 31443 | B2: 12 | G2: =B1&" - NFIB" -> Expect Real Sales to Improve - NFIB | U2: =D1&" - NFIB" -> Expect Real Sales to Improve YoY - NFIB
A3: 31471 | B3: 13
A4: 31502 | B4: 18 | C4: =AVERAGE(B2:B4) -> 14.333333
A5: 31532 | B5: 16 | C5: =AVERAGE(B3:B5) -> 15.666667
A6: 31563 | B6: 13 | C6: =AVERAGE(B4:B6) -> 15.666667
A7: 31593 | B7: 17 | C7: =AVERAGE(B5:B7) -> 15.333333
A8: 31624 | B8: 9 | C8: =AVERAGE(B6:B8) -> 13
A9: 31655 | B9: 10 | C9: =AVERAGE(B7:B9) -> 12
A10: 31685 | B10: 6 | C10: =AVERAGE(B8:B10) -> 8.3333333
A11: 31716 | B11: 7 | C11: =AVERAGE(B9:B11) -> 7.6666667
A12: 31746 | B12: 5 | C12: =AVERAGE(B10:B12) -> 6
A13: 31777 | B13: 5 | C13: =AVERAGE(B11:B13) -> 5.6666667
A14: 31808 | B14: 8 | C14: =AVERAGE(B12:B14) -> 6 | D14: =B14-B2 -> -4
A15: 31836 | B15: 12 | C15: =AVERAGE(B13:B15) -> 8.3333333 | D15: =B15-B3 -> -1
A16: 31867 | B16: 10 | C16: =AVERAGE(B14:B16) -> 10 | D16: =B16-B4 -> -8 | E16: =C16-C4 -> -4.3333333
A17: 31897 | B17: 6 | C17: =AVERAGE(B15:B17) -> 9.3333333 | D17: =B17-B5 -> -10 | E17: =C17-C5 -> -6.3333333
A18: 31928 | B18: 1 | C18: =AVERAGE(B16:B18) -> 5.6666667 | D18: =B18-B6 -> -12 | E18: =C18-C6 -> -10
A19: 31958 | B19: 9 | C19: =AVERAGE(B17:B19) -> 5.3333333 | D19: =B19-B7 -> -8 | E19: =C19-C7 -> -10
A20: 31989 | B20: 10 | C20: =AVERAGE(B18:B20) -> 6.6666667 | D20: =B20-B8 -> 1 | E20: =C20-C8 -> -6.3333333
A21: 32020 | B21: 16 | C21: =AVERAGE(B19:B21) -> 11.666667 | D21: =B21-B9 -> 6 | E21: =C21-C9 -> -0.33333333
A22: 32050 | B22: 9 | C22: =AVERAGE(B20:B22) -> 11.666667 | D22: =B22-B10 -> 3 | E22: =C22-C10 -> 3.3333333
A23: 32081 | B23: 9 | C23: =AVERAGE(B21:B23) -> 11.333333 | D23: =B23-B11 -> 2 | E23: =C23-C11 -> 3.6666667
A24: 32111 | B24: 1 | C24: =AVERAGE(B22:B24) -> 6.3333333 | D24: =B24-B12 -> -4 | E24: =C24-C12 -> 0.33333333
A25: 32142 | B25: -4 | C25: =AVERAGE(B23:B25) -> 2 | D25: =B25-B13 -> -9 | E25: =C25-C13 -> -3.6666667
A26: 32173 | B26: 1 | C26: =AVERAGE(B24:B26) -> -0.66666667 | D26: =B26-B14 -> -7 | E26: =C26-C14 -> -6.6666667
A27: 32202 | B27: 0 | C27: =AVERAGE(B25:B27) -> -1 | D27: =B27-B15 -> -12 | E27: =C27-C15 -> -9.3333333 | G27: =B1&" - NFIB - 2000-" -> Expect Real Sales to Improve - NFIB - 2000- | U27: =D1&" - NFIB - 2000-" -> Expect Real Sales to Improve YoY - NFIB - 2000-
A28: 32233 | B28: 6 | C28: =AVERAGE(B26:B28) -> 2.3333333 | D28: =B28-B16 -> -4 | E28: =C28-C16 -> -7.6666667
A29: 32263 | B29: 5 | C29: =AVERAGE(B27:B29) -> 3.6666667 | D29: =B29-B17 -> -1 | E29: =C29-C17 -> -5.6666667
A30: 32294 | B30: 0 | C30: =AVERAGE(B28:B30) -> 3.6666667 | D30: =B30-B18 -> -1 | E30: =C30-C18 -> -2
A31: 32324 | B31: 4 | C31: =AVERAGE(B29:B31) -> 3 | D31: =B31-B19 -> -5 | E31: =C31-C19 -> -2.3333333
A32: 32355 | B32: 1 | C32: =AVERAGE(B30:B32) -> 1.6666667 | D32: =B32-B20 -> -9 | E32: =C32-C20 -> -5
A33: 32386 | B33: 5 | C33: =AVERAGE(B31:B33) -> 3.3333333 | D33: =B33-B21 -> -11 | E33: =C33-C21 -> -8.3333333
A34: 32416 | B34: 2 | C34: =AVERAGE(B32:B34) -> 2.6666667 | D34: =B34-B22 -> -7 | E34: =C34-C22 -> -9
A35: 32447 | B35: 9 | C35: =AVERAGE(B33:B35) -> 5.3333333 | D35: =B35-B23 -> 0 | E35: =C35-C23 -> -6
A36: 32477 | B36: 8 | C36: =AVERAGE(B34:B36) -> 6.3333333 | D36: =B36-B24 -> 7 | E36: =C36-C24 -> 0
A37: 32508 | B37: 4 | C37: =AVERAGE(B35:B37) -> 7 | D37: =B37-B25 -> 8 | E37: =C37-C25 -> 5
A38: 32539 | B38: 4 | C38: =AVERAGE(B36:B38) -> 5.3333333 | D38: =B38-B26 -> 3 | E38: =C38-C26 -> 6
A39: 32567 | B39: 5 | C39: =AVERAGE(B37:B39) -> 4.3333333 | D39: =B39-B27 -> 5 | E39: =C39-C27 -> 5.3333333
... A51: 32932 | B51: 3 | C51: =AVERAGE(B49:B51) -> 4.3333333 | D51: =B51-B39 -> -2 | E51: =C51-C39 -> 0
...

Sheet Capital Plans
B1: Plans to Make Capital Outlays | C1: =B1&" - 3mma" -> Plans to Make Capital Outlays - 3mma | D1: =B1&" YoY" -> Plans to Make Capital Outlays YoY | E1: =C1&" YoY" -> Plans to Make Capital Outlays - 3mma YoY
A2: 31443 | B2: 31 | G2: =B1&" - NFIB" -> Plans to Make Capital Outlays - NFIB | U2: =D1&" - NFIB" -> Plans to Make Capital Outlays YoY - NFIB
A3: 31471 | B3: 29
A4: 31502 | B4: 28 | C4: =AVERAGE(B2:B4) -> 29.333333
A5: 31532 | B5: 32 | C5: =AVERAGE(B3:B5) -> 29.666667
A6: 31563 | B6: 34 | C6: =AVERAGE(B4:B6) -> 31.333333
A7: 31593 | B7: 30 | C7: =AVERAGE(B5:B7) -> 32
A8: 31624 | B8: 31 | C8: =AVERAGE(B6:B8) -> 31.666667
A9: 31655 | B9: 30 | C9: =AVERAGE(B7:B9) -> 30.333333
A10: 31685 | B10: 30 | C10: =AVERAGE(B8:B10) -> 30.333333
A11: 31716 | B11: 30 | C11: =AVERAGE(B9:B11) -> 30
A12: 31746 | B12: 28 | C12: =AVERAGE(B10:B12) -> 29.333333
A13: 31777 | B13: 29 | C13: =AVERAGE(B11:B13) -> 29
A14: 31808 | B14: 30 | C14: =AVERAGE(B12:B14) -> 29 | D14: =B14-B2 -> -1
A15: 31836 | B15: 29 | C15: =AVERAGE(B13:B15) -> 29.333333 | D15: =B15-B3 -> 0
A16: 31867 | B16: 33 | C16: =AVERAGE(B14:B16) -> 30.666667 | D16: =B16-B4 -> 5 | E16: =C16-C4 -> 1.3333333
A17: 31897 | B17: 31 | C17: =AVERAGE(B15:B17) -> 31 | D17: =B17-B5 -> -1 | E17: =C17-C5 -> 1.3333333
A18: 31928 | B18: 30 | C18: =AVERAGE(B16:B18) -> 31.333333 | D18: =B18-B6 -> -4 | E18: =C18-C6 -> 0
A19: 31958 | B19: 34 | C19: =AVERAGE(B17:B19) -> 31.666667 | D19: =B19-B7 -> 4 | E19: =C19-C7 -> -0.33333333
A20: 31989 | B20: 35 | C20: =AVERAGE(B18:B20) -> 33 | D20: =B20-B8 -> 4 | E20: =C20-C8 -> 1.3333333
A21: 32020 | B21: 32 | C21: =AVERAGE(B19:B21) -> 33.666667 | D21: =B21-B9 -> 2 | E21: =C21-C9 -> 3.3333333
A22: 32050 | B22: 31 | C22: =AVERAGE(B20:B22) -> 32.666667 | D22: =B22-B10 -> 1 | E22: =C22-C10 -> 2.3333333
A23: 32081 | B23: 31 | C23: =AVERAGE(B21:B23) -> 31.333333 | D23: =B23-B11 -> 1 | E23: =C23-C11 -> 1.3333333
A24: 32111 | B24: 29 | C24: =AVERAGE(B22:B24) -> 30.333333 | D24: =B24-B12 -> 1 | E24: =C24-C12 -> 1
A25: 32142 | B25: 30 | C25: =AVERAGE(B23:B25) -> 30 | D25: =B25-B13 -> 1 | E25: =C25-C13 -> 1
A26: 32173 | B26: 34 | C26: =AVERAGE(B24:B26) -> 31 | D26: =B26-B14 -> 4 | E26: =C26-C14 -> 2
A27: 32202 | B27: 32 | C27: =AVERAGE(B25:B27) -> 32 | D27: =B27-B15 -> 3 | E27: =C27-C15 -> 2.6666667 | G27: =B1&" - NFIB - 2000-" -> Plans to Make Capital Outlays - NFIB - 2000- | U27: =D1&" - NFIB - 2000-" -> Plans to Make Capital Outlays YoY - NFIB - 2000-
A28: 32233 | B28: 32 | C28: =AVERAGE(B26:B28) -> 32.666667 | D28: =B28-B16 -> -1 | E28: =C28-C16 -> 2
A29: 32263 | B29: 32 | C29: =AVERAGE(B27:B29) -> 32 | D29: =B29-B17 -> 1 | E29: =C29-C17 -> 1
A30: 32294 | B30: 33 | C30: =AVERAGE(B28:B30) -> 32.333333 | D30: =B30-B18 -> 3 | E30: =C30-C18 -> 1
A31: 32324 | B31: 31 | C31: =AVERAGE(B29:B31) -> 32 | D31: =B31-B19 -> -3 | E31: =C31-C19 -> 0.33333333
A32: 32355 | B32: 31 | C32: =AVERAGE(B30:B32) -> 31.666667 | D32: =B32-B20 -> -4 | E32: =C32-C20 -> -1.3333333
A33: 32386 | B33: 31 | C33: =AVERAGE(B31:B33) -> 31 | D33: =B33-B21 -> -1 | E33: =C33-C21 -> -2.6666667
A34: 32416 | B34: 32 | C34: =AVERAGE(B32:B34) -> 31.333333 | D34: =B34-B22 -> 1 | E34: =C34-C22 -> -1.3333333
A35: 32447 | B35: 35 | C35: =AVERAGE(B33:B35) -> 32.666667 | D35: =B35-B23 -> 4 | E35: =C35-C23 -> 1.3333333
A36: 32477 | B36: 34 | C36: =AVERAGE(B34:B36) -> 33.666667 | D36: =B36-B24 -> 5 | E36: =C36-C24 -> 3.3333333
A37: 32508 | B37: 33 | C37: =AVERAGE(B35:B37) -> 34 | D37: =B37-B25 -> 3 | E37: =C37-C25 -> 4
A38: 32539 | B38: 35 | C38: =AVERAGE(B36:B38) -> 34 | D38: =B38-B26 -> 1 | E38: =C38-C26 -> 3
A39: 32567 | B39: 32 | C39: =AVERAGE(B37:B39) -> 33.333333 | D39: =B39-B27 -> 0 | E39: =C39-C27 -> 1.3333333
... A51: 32932 | B51: 34 | C51: =AVERAGE(B49:B51) -> 33.666667 | D51: =B51-B39 -> 2 | E51: =C51-C39 -> 0.33333333
...

Sheet Current Inventory
B1: Current Inventory | C1: =B1&" - 3mma" -> Current Inventory - 3mma | D1: =B1&" YoY" -> Current Inventory YoY | E1: =C1&" YoY" -> Current Inventory - 3mma YoY
A2: 31443 | B2: -2 | G2: =B1&" - NFIB" -> Current Inventory - NFIB | U2: =D1&" - NFIB" -> Current Inventory YoY - NFIB
A3: 31471 | B3: -2
A4: 31502 | B4: -3 | C4: =AVERAGE(B2:B4) -> -2.3333333
A5: 31532 | B5: -3 | C5: =AVERAGE(B3:B5) -> -2.6666667
A6: 31563 | B6: 1 | C6: =AVERAGE(B4:B6) -> -1.6666667
A7: 31593 | B7: -4 | C7: =AVERAGE(B5:B7) -> -2
A8: 31624 | B8: -3 | C8: =AVERAGE(B6:B8) -> -2
A9: 31655 | B9: -4 | C9: =AVERAGE(B7:B9) -> -3.6666667
A10: 31685 | B10: -1 | C10: =AVERAGE(B8:B10) -> -2.6666667
A11: 31716 | B11: -2 | C11: =AVERAGE(B9:B11) -> -2.3333333
A12: 31746 | B12: -6 | C12: =AVERAGE(B10:B12) -> -3
A13: 31777 | B13: -1 | C13: =AVERAGE(B11:B13) -> -3
A14: 31808 | B14: -3 | C14: =AVERAGE(B12:B14) -> -3.3333333 | D14: =B14-B2 -> -1
A15: 31836 | B15: -2 | C15: =AVERAGE(B13:B15) -> -2 | D15: =B15-B3 -> 0
A16: 31867 | B16: 0 | C16: =AVERAGE(B14:B16) -> -1.6666667 | D16: =B16-B4 -> 3 | E16: =C16-C4 -> 0.66666667
A17: 31897 | B17: -1 | C17: =AVERAGE(B15:B17) -> -1 | D17: =B17-B5 -> 2 | E17: =C17-C5 -> 1.6666667
A18: 31928 | B18: -1 | C18: =AVERAGE(B16:B18) -> -0.66666667 | D18: =B18-B6 -> -2 | E18: =C18-C6 -> 1
A19: 31958 | B19: -3 | C19: =AVERAGE(B17:B19) -> -1.6666667 | D19: =B19-B7 -> 1 | E19: =C19-C7 -> 0.33333333
A20: 31989 | B20: 0 | C20: =AVERAGE(B18:B20) -> -1.3333333 | D20: =B20-B8 -> 3 | E20: =C20-C8 -> 0.66666667
A21: 32020 | B21: -1 | C21: =AVERAGE(B19:B21) -> -1.3333333 | D21: =B21-B9 -> 3 | E21: =C21-C9 -> 2.3333333
A22: 32050 | B22: -1 | C22: =AVERAGE(B20:B22) -> -0.66666667 | D22: =B22-B10 -> 0 | E22: =C22-C10 -> 2
A23: 32081 | B23: 0 | C23: =AVERAGE(B21:B23) -> -0.66666667 | D23: =B23-B11 -> 2 | E23: =C23-C11 -> 1.6666667
A24: 32111 | B24: -2 | C24: =AVERAGE(B22:B24) -> -1 | D24: =B24-B12 -> 4 | E24: =C24-C12 -> 2
A25: 32142 | B25: 0 | C25: =AVERAGE(B23:B25) -> -0.66666667 | D25: =B25-B13 -> 1 | E25: =C25-C13 -> 2.3333333
A26: 32173 | B26: -5 | C26: =AVERAGE(B24:B26) -> -2.3333333 | D26: =B26-B14 -> -2 | E26: =C26-C14 -> 1
A27: 32202 | B27: -3 | C27: =AVERAGE(B25:B27) -> -2.6666667 | D27: =B27-B15 -> -1 | E27: =C27-C15 -> -0.66666667 | G27: =B1&" - NFIB - 2000-" -> Current Inventory - NFIB - 2000- | U27: =D1&" - NFIB - 2000-" -> Current Inventory YoY - NFIB - 2000-
A28: 32233 | B28: -1 | C28: =AVERAGE(B26:B28) -> -3 | D28: =B28-B16 -> -1 | E28: =C28-C16 -> -1.3333333
A29: 32263 | B29: -2 | C29: =AVERAGE(B27:B29) -> -2 | D29: =B29-B17 -> -1 | E29: =C29-C17 -> -1
A30: 32294 | B30: -2 | C30: =AVERAGE(B28:B30) -> -1.6666667 | D30: =B30-B18 -> -1 | E30: =C30-C18 -> -1
A31: 32324 | B31: -2 | C31: =AVERAGE(B29:B31) -> -2 | D31: =B31-B19 -> 1 | E31: =C31-C19 -> -0.33333333
A32: 32355 | B32: -2 | C32: =AVERAGE(B30:B32) -> -2 | D32: =B32-B20 -> -2 | E32: =C32-C20 -> -0.66666667
A33: 32386 | B33: -4 | C33: =AVERAGE(B31:B33) -> -2.6666667 | D33: =B33-B21 -> -3 | E33: =C33-C21 -> -1.3333333
A34: 32416 | B34: -3 | C34: =AVERAGE(B32:B34) -> -3 | D34: =B34-B22 -> -2 | E34: =C34-C22 -> -2.3333333
A35: 32447 | B35: 0 | C35: =AVERAGE(B33:B35) -> -2.3333333 | D35: =B35-B23 -> 0 | E35: =C35-C23 -> -1.6666667
A36: 32477 | B36: -2 | C36: =AVERAGE(B34:B36) -> -1.6666667 | D36: =B36-B24 -> 0 | E36: =C36-C24 -> -0.66666667
A37: 32508 | B37: -5 | C37: =AVERAGE(B35:B37) -> -2.3333333 | D37: =B37-B25 -> -5 | E37: =C37-C25 -> -1.6666667
A38: 32539 | B38: -2 | C38: =AVERAGE(B36:B38) -> -3 | D38: =B38-B26 -> 3 | E38: =C38-C26 -> -0.66666667
A39: 32567 | B39: -2 | C39: =AVERAGE(B37:B39) -> -3 | D39: =B39-B27 -> 1 | E39: =C39-C27 -> -0.33333333
... A51: 32932 | B51: -3 | C51: =AVERAGE(B49:B51) -> -3.3333333 | D51: =B51-B39 -> -1 | E51: =C51-C39 -> -0.33333333
...

Sheet Current Job Openings
B1: Current Job Openings | C1: =B1&" - 3mma" -> Current Job Openings - 3mma | D1: =B1&" YoY" -> Current Job Openings YoY | E1: =C1&" YoY" -> Current Job Openings - 3mma YoY
A2: 31443 | B2: 18 | G2: =B1&" - NFIB" -> Current Job Openings - NFIB | U2: =D1&" - NFIB" -> Current Job Openings YoY - NFIB
A3: 31471 | B3: 15
A4: 31502 | B4: 19 | C4: =AVERAGE(B2:B4) -> 17.333333
A5: 31532 | B5: 16 | C5: =AVERAGE(B3:B5) -> 16.666667
A6: 31563 | B6: 15 | C6: =AVERAGE(B4:B6) -> 16.666667
A7: 31593 | B7: 18 | C7: =AVERAGE(B5:B7) -> 16.333333
A8: 31624 | B8: 16 | C8: =AVERAGE(B6:B8) -> 16.333333
A9: 31655 | B9: 16 | C9: =AVERAGE(B7:B9) -> 16.666667
A10: 31685 | B10: 14 | C10: =AVERAGE(B8:B10) -> 15.333333
A11: 31716 | B11: 17 | C11: =AVERAGE(B9:B11) -> 15.666667
A12: 31746 | B12: 18 | C12: =AVERAGE(B10:B12) -> 16.333333
A13: 31777 | B13: 17 | C13: =AVERAGE(B11:B13) -> 17.333333
A14: 31808 | B14: 17 | C14: =AVERAGE(B12:B14) -> 17.333333 | D14: =B14-B2 -> -1
A15: 31836 | B15: 20 | C15: =AVERAGE(B13:B15) -> 18 | D15: =B15-B3 -> 5
A16: 31867 | B16: 18 | C16: =AVERAGE(B14:B16) -> 18.333333 | D16: =B16-B4 -> -1 | E16: =C16-C4 -> 1
A17: 31897 | B17: 19 | C17: =AVERAGE(B15:B17) -> 19 | D17: =B17-B5 -> 3 | E17: =C17-C5 -> 2.3333333
